Traceback (most recent call last):
  File "/data-hdd/xiechenjia/miniconda/miniconda/envs/torchsnn/lib/python3.7/site-packages/torch/cuda/__init__.py", line 242, in _lazy_init
    queued_call()
  File "/data-hdd/xiechenjia/miniconda/miniconda/envs/torchsnn/lib/python3.7/site-packages/torch/cuda/__init__.py", line 125, in _check_capability
    capability = get_device_capability(d)
  File "/data-hdd/xiechenjia/miniconda/miniconda/envs/torchsnn/lib/python3.7/site-packages/torch/cuda/__init__.py", line 357, in get_device_capability
    prop = get_device_properties(device)
  File "/data-hdd/xiechenjia/miniconda/miniconda/envs/torchsnn/lib/python3.7/site-packages/torch/cuda/__init__.py", line 375, in get_device_properties
    return _get_device_properties(device)  # type: ignore[name-defined]
RuntimeError: device >= 0 && device < num_gpus INTERNAL ASSERT FAILED at "../aten/src/ATen/cuda/CUDAContext.cpp":50, please report a bug to PyTorch. 

The above exception was the direct cause of the following exception:

Traceback (most recent call last):
  File "lenet5.py", line 87, in <module>
    train_ch5(net, train_iter, test_iter, batch_size, optimizer, device, num_epochs)
  File "lenet5.py", line 61, in train_ch5
    net = net.to(device)
  File "/data-hdd/xiechenjia/miniconda/miniconda/envs/torchsnn/lib/python3.7/site-packages/torch/nn/modules/module.py", line 989, in to
    return self._apply(convert)
  File "/data-hdd/xiechenjia/miniconda/miniconda/envs/torchsnn/lib/python3.7/site-packages/torch/nn/modules/module.py", line 641, in _apply
    module._apply(fn)
  File "/data-hdd/xiechenjia/miniconda/miniconda/envs/torchsnn/lib/python3.7/site-packages/torch/nn/modules/module.py", line 641, in _apply
    module._apply(fn)
  File "/data-hdd/xiechenjia/miniconda/miniconda/envs/torchsnn/lib/python3.7/site-packages/torch/nn/modules/module.py", line 664, in _apply
    param_applied = fn(param)
  File "/data-hdd/xiechenjia/miniconda/miniconda/envs/torchsnn/lib/python3.7/site-packages/torch/nn/modules/module.py", line 987, in convert
    return t.to(device, dtype if t.is_floating_point() or t.is_complex() else None, non_blocking)
  File "/data-hdd/xiechenjia/miniconda/miniconda/envs/torchsnn/lib/python3.7/site-packages/torch/cuda/__init__.py", line 246, in _lazy_init
    raise DeferredCudaCallError(msg) from e
torch.cuda.DeferredCudaCallError: CUDA call failed lazily at initialization with error: device >= 0 && device < num_gpus INTERNAL ASSERT FAILED at "../aten/src/ATen/cuda/CUDAContext.cpp":50, please report a bug to PyTorch. 

CUDA call was originally invoked at:

['  File "lenet5.py", line 3, in <module>\n    import torch\n', '  File "<frozen importlib._bootstrap>", line 983, in _find_and_load\n', '  File "<frozen importlib._bootstrap>", line 967, in _find_and_load_unlocked\n', '  File "<frozen importlib._bootstrap>", line 677, in _load_unlocked\n', '  File "<frozen importlib._bootstrap_external>", line 728, in exec_module\n', '  File "<frozen importlib._bootstrap>", line 219, in _call_with_frames_removed\n', '  File "/data-hdd/xiechenjia/miniconda/miniconda/envs/torchsnn/lib/python3.7/site-packages/torch/__init__.py", line 798, in <module>\n    _C._initExtension(manager_path())\n', '  File "<frozen importlib._bootstrap>", line 983, in _find_and_load\n', '  File "<frozen importlib._bootstrap>", line 967, in _find_and_load_unlocked\n', '  File "<frozen importlib._bootstrap>", line 677, in _load_unlocked\n', '  File "<frozen importlib._bootstrap_external>", line 728, in exec_module\n', '  File "<frozen importlib._bootstrap>", line 219, in _call_with_frames_removed\n', '  File "/data-hdd/xiechenjia/miniconda/miniconda/envs/torchsnn/lib/python3.7/site-packages/torch/cuda/__init__.py", line 179, in <module>\n    _lazy_call(_check_capability)\n', '  File "/data-hdd/xiechenjia/miniconda/miniconda/envs/torchsnn/lib/python3.7/site-packages/torch/cuda/__init__.py", line 177, in _lazy_call\n    _queued_calls.append((callable, traceback.format_stack()))\n']
